<?xml version="1.0" encoding="utf-8"?><testsuites><testsuite name="pytest" errors="7" failures="0" skipped="0" tests="7" time="6.991" timestamp="2025-04-10T13:48:03.193040+00:00" hostname="codespaces-703d42"><testcase classname="" name="app.tests.standalone.test_appointment" time="0.000"><error message="collection failure">ImportError while importing test module '/workspaces/Novamind-Backend-ONLY-TWINS/backend/app/tests/standalone/test_appointment.py'.
Hint: make sure your test modules/packages have valid Python names.
Traceback:
/usr/local/python/3.12.1/lib/python3.12/site-packages/_pytest/python.py:493: in importtestmodule
    mod = import_path(
/usr/local/python/3.12.1/lib/python3.12/site-packages/_pytest/pathlib.py:587: in import_path
    importlib.import_module(module_name)
/usr/local/python/3.12.1/lib/python3.12/importlib/__init__.py:90: in import_module
    return _bootstrap._gcd_import(name[level:], package, level)
&lt;frozen importlib._bootstrap&gt;:1387: in _gcd_import
    ???
&lt;frozen importlib._bootstrap&gt;:1360: in _find_and_load
    ???
&lt;frozen importlib._bootstrap&gt;:1331: in _find_and_load_unlocked
    ???
&lt;frozen importlib._bootstrap&gt;:935: in _load_unlocked
    ???
/usr/local/python/3.12.1/lib/python3.12/site-packages/_pytest/assertion/rewrite.py:185: in exec_module
    exec(co, module.__dict__)
backend/app/tests/standalone/test_appointment.py:10: in &lt;module&gt;
    from app.domain.entities.appointment import (
backend/app/domain/entities/appointment.py:14: in &lt;module&gt;
    from app.domain.exceptions import (
E   ImportError: cannot import name 'AppointmentConflictError' from 'app.domain.exceptions' (/workspaces/Novamind-Backend-ONLY-TWINS/backend/app/domain/exceptions/__init__.py)</error></testcase><testcase classname="" name="app.tests.standalone.test_biometric_event_processor" time="0.000"><error message="collection failure">ImportError while importing test module '/workspaces/Novamind-Backend-ONLY-TWINS/backend/app/tests/standalone/test_biometric_event_processor.py'.
Hint: make sure your test modules/packages have valid Python names.
Traceback:
/usr/local/python/3.12.1/lib/python3.12/site-packages/_pytest/python.py:493: in importtestmodule
    mod = import_path(
/usr/local/python/3.12.1/lib/python3.12/site-packages/_pytest/pathlib.py:587: in import_path
    importlib.import_module(module_name)
/usr/local/python/3.12.1/lib/python3.12/importlib/__init__.py:90: in import_module
    return _bootstrap._gcd_import(name[level:], package, level)
&lt;frozen importlib._bootstrap&gt;:1387: in _gcd_import
    ???
&lt;frozen importlib._bootstrap&gt;:1360: in _find_and_load
    ???
&lt;frozen importlib._bootstrap&gt;:1331: in _find_and_load_unlocked
    ???
&lt;frozen importlib._bootstrap&gt;:935: in _load_unlocked
    ???
/usr/local/python/3.12.1/lib/python3.12/site-packages/_pytest/assertion/rewrite.py:185: in exec_module
    exec(co, module.__dict__)
backend/app/tests/standalone/test_biometric_event_processor.py:15: in &lt;module&gt;
    from app.domain.entities.biometric_twin import BiometricDataPoint
backend/app/domain/entities/biometric_twin.py:13: in &lt;module&gt;
    from pydantic import BaseModel, Field, validator
E   ModuleNotFoundError: No module named 'pydantic'</error></testcase><testcase classname="" name="app.tests.standalone.test_mfa_service" time="0.000"><error message="collection failure">ImportError while importing test module '/workspaces/Novamind-Backend-ONLY-TWINS/backend/app/tests/standalone/test_mfa_service.py'.
Hint: make sure your test modules/packages have valid Python names.
Traceback:
/usr/local/python/3.12.1/lib/python3.12/site-packages/_pytest/python.py:493: in importtestmodule
    mod = import_path(
/usr/local/python/3.12.1/lib/python3.12/site-packages/_pytest/pathlib.py:587: in import_path
    importlib.import_module(module_name)
/usr/local/python/3.12.1/lib/python3.12/importlib/__init__.py:90: in import_module
    return _bootstrap._gcd_import(name[level:], package, level)
&lt;frozen importlib._bootstrap&gt;:1387: in _gcd_import
    ???
&lt;frozen importlib._bootstrap&gt;:1360: in _find_and_load
    ???
&lt;frozen importlib._bootstrap&gt;:1331: in _find_and_load_unlocked
    ???
&lt;frozen importlib._bootstrap&gt;:935: in _load_unlocked
    ???
/usr/local/python/3.12.1/lib/python3.12/site-packages/_pytest/assertion/rewrite.py:185: in exec_module
    exec(co, module.__dict__)
backend/app/tests/standalone/test_mfa_service.py:10: in &lt;module&gt;
    from app.infrastructure.security.mfa_service import (
backend/app/infrastructure/security/mfa_service.py:18: in &lt;module&gt;
    import pyotp
E   ModuleNotFoundError: No module named 'pyotp'</error></testcase><testcase classname="" name="app.tests.standalone.test_pat_mock" time="0.000"><error message="collection failure">ImportError while importing test module '/workspaces/Novamind-Backend-ONLY-TWINS/backend/app/tests/standalone/test_pat_mock.py'.
Hint: make sure your test modules/packages have valid Python names.
Traceback:
/usr/local/python/3.12.1/lib/python3.12/site-packages/_pytest/python.py:493: in importtestmodule
    mod = import_path(
/usr/local/python/3.12.1/lib/python3.12/site-packages/_pytest/pathlib.py:587: in import_path
    importlib.import_module(module_name)
/usr/local/python/3.12.1/lib/python3.12/importlib/__init__.py:90: in import_module
    return _bootstrap._gcd_import(name[level:], package, level)
&lt;frozen importlib._bootstrap&gt;:1387: in _gcd_import
    ???
&lt;frozen importlib._bootstrap&gt;:1360: in _find_and_load
    ???
&lt;frozen importlib._bootstrap&gt;:1331: in _find_and_load_unlocked
    ???
&lt;frozen importlib._bootstrap&gt;:935: in _load_unlocked
    ???
/usr/local/python/3.12.1/lib/python3.12/site-packages/_pytest/assertion/rewrite.py:185: in exec_module
    exec(co, module.__dict__)
backend/app/tests/standalone/test_pat_mock.py:13: in &lt;module&gt;
    from app.core.services.ml.pat.exceptions import (
backend/app/core/services/ml/__init__.py:12: in &lt;module&gt;
    from app.core.services.ml.factory import MLServiceFactory, MLServiceCache
backend/app/core/services/ml/factory.py:14: in &lt;module&gt;
    from app.core.services.ml.phi_detection import AWSComprehendMedicalPHIDetection
backend/app/core/services/ml/phi_detection.py:12: in &lt;module&gt;
    import boto3
E   ModuleNotFoundError: No module named 'boto3'</error></testcase><testcase classname="" name="app.tests.standalone.test_patient" time="0.000"><error message="collection failure">ImportError while importing test module '/workspaces/Novamind-Backend-ONLY-TWINS/backend/app/tests/standalone/test_patient.py'.
Hint: make sure your test modules/packages have valid Python names.
Traceback:
/usr/local/python/3.12.1/lib/python3.12/site-packages/_pytest/python.py:493: in importtestmodule
    mod = import_path(
/usr/local/python/3.12.1/lib/python3.12/site-packages/_pytest/pathlib.py:587: in import_path
    importlib.import_module(module_name)
/usr/local/python/3.12.1/lib/python3.12/importlib/__init__.py:90: in import_module
    return _bootstrap._gcd_import(name[level:], package, level)
&lt;frozen importlib._bootstrap&gt;:1387: in _gcd_import
    ???
&lt;frozen importlib._bootstrap&gt;:1360: in _find_and_load
    ???
&lt;frozen importlib._bootstrap&gt;:1331: in _find_and_load_unlocked
    ???
&lt;frozen importlib._bootstrap&gt;:935: in _load_unlocked
    ???
/usr/local/python/3.12.1/lib/python3.12/site-packages/_pytest/assertion/rewrite.py:185: in exec_module
    exec(co, module.__dict__)
backend/app/tests/standalone/test_patient.py:10: in &lt;module&gt;
    from app.domain.entities.patient import (
E   ImportError: cannot import name 'InsuranceStatus' from 'app.domain.entities.patient' (/workspaces/Novamind-Backend-ONLY-TWINS/backend/app/domain/entities/patient.py)</error></testcase><testcase classname="" name="app.tests.standalone.test_phi_sanitizer" time="0.000"><error message="collection failure">ImportError while importing test module '/workspaces/Novamind-Backend-ONLY-TWINS/backend/app/tests/standalone/test_phi_sanitizer.py'.
Hint: make sure your test modules/packages have valid Python names.
Traceback:
/usr/local/python/3.12.1/lib/python3.12/site-packages/_pytest/python.py:493: in importtestmodule
    mod = import_path(
/usr/local/python/3.12.1/lib/python3.12/site-packages/_pytest/pathlib.py:587: in import_path
    importlib.import_module(module_name)
/usr/local/python/3.12.1/lib/python3.12/importlib/__init__.py:90: in import_module
    return _bootstrap._gcd_import(name[level:], package, level)
&lt;frozen importlib._bootstrap&gt;:1387: in _gcd_import
    ???
&lt;frozen importlib._bootstrap&gt;:1360: in _find_and_load
    ???
&lt;frozen importlib._bootstrap&gt;:1331: in _find_and_load_unlocked
    ???
&lt;frozen importlib._bootstrap&gt;:935: in _load_unlocked
    ???
/usr/local/python/3.12.1/lib/python3.12/site-packages/_pytest/assertion/rewrite.py:185: in exec_module
    exec(co, module.__dict__)
backend/app/tests/standalone/test_phi_sanitizer.py:7: in &lt;module&gt;
    from app.infrastructure.security.log_sanitizer import PHISanitizer
E   ImportError: cannot import name 'PHISanitizer' from 'app.infrastructure.security.log_sanitizer' (/workspaces/Novamind-Backend-ONLY-TWINS/backend/app/infrastructure/security/log_sanitizer.py)</error></testcase><testcase classname="" name="app.tests.standalone.test_temporal" time="0.000"><error message="collection failure">ImportError while importing test module '/workspaces/Novamind-Backend-ONLY-TWINS/backend/app/tests/standalone/test_temporal.py'.
Hint: make sure your test modules/packages have valid Python names.
Traceback:
/usr/local/python/3.12.1/lib/python3.12/site-packages/_pytest/python.py:493: in importtestmodule
    mod = import_path(
/usr/local/python/3.12.1/lib/python3.12/site-packages/_pytest/pathlib.py:587: in import_path
    importlib.import_module(module_name)
/usr/local/python/3.12.1/lib/python3.12/importlib/__init__.py:90: in import_module
    return _bootstrap._gcd_import(name[level:], package, level)
&lt;frozen importlib._bootstrap&gt;:1387: in _gcd_import
    ???
&lt;frozen importlib._bootstrap&gt;:1360: in _find_and_load
    ???
&lt;frozen importlib._bootstrap&gt;:1331: in _find_and_load_unlocked
    ???
&lt;frozen importlib._bootstrap&gt;:935: in _load_unlocked
    ???
/usr/local/python/3.12.1/lib/python3.12/site-packages/_pytest/assertion/rewrite.py:185: in exec_module
    exec(co, module.__dict__)
backend/app/tests/standalone/test_temporal.py:14: in &lt;module&gt;
    from app.domain.entities.digital_twin.temporal import (
E   ModuleNotFoundError: No module named 'app.domain.entities.digital_twin.temporal'</error></testcase></testsuite></testsuites>